[2024-01-31T18:52:20.965+0000] {taskinstance.py:1159} INFO - Dependencies all met for dep_context=non-requeueable deps ti=<TaskInstance: user_automation.stream_data_from_api manual__2024-01-31T18:52:17.409015+00:00 [queued]>
[2024-01-31T18:52:20.984+0000] {taskinstance.py:1159} INFO - Dependencies all met for dep_context=requeueable deps ti=<TaskInstance: user_automation.stream_data_from_api manual__2024-01-31T18:52:17.409015+00:00 [queued]>
[2024-01-31T18:52:20.986+0000] {taskinstance.py:1361} INFO - Starting attempt 1 of 1
[2024-01-31T18:52:21.010+0000] {taskinstance.py:1382} INFO - Executing <Task(PythonOperator): stream_data_from_api> on 2024-01-31 18:52:17.409015+00:00
[2024-01-31T18:52:21.014+0000] {standard_task_runner.py:57} INFO - Started process 51 to run task
[2024-01-31T18:52:21.018+0000] {standard_task_runner.py:84} INFO - Running: ['***', 'tasks', 'run', 'user_automation', 'stream_data_from_api', 'manual__2024-01-31T18:52:17.409015+00:00', '--job-id', '26', '--raw', '--subdir', 'DAGS_FOLDER/kafkastream.py', '--cfg-path', '/tmp/tmpc4h_z2kx']
[2024-01-31T18:52:21.021+0000] {standard_task_runner.py:85} INFO - Job 26: Subtask stream_data_from_api
[2024-01-31T18:52:21.142+0000] {task_command.py:415} INFO - Running <TaskInstance: user_automation.stream_data_from_api manual__2024-01-31T18:52:17.409015+00:00 [running]> on host 9654d1909d72
[2024-01-31T18:52:21.335+0000] {taskinstance.py:1660} INFO - Exporting env vars: AIRFLOW_CTX_DAG_OWNER='***' AIRFLOW_CTX_DAG_ID='user_automation' AIRFLOW_CTX_TASK_ID='stream_data_from_api' AIRFLOW_CTX_EXECUTION_DATE='2024-01-31T18:52:17.409015+00:00' AIRFLOW_CTX_TRY_NUMBER='1' AIRFLOW_CTX_DAG_RUN_ID='manual__2024-01-31T18:52:17.409015+00:00'
[2024-01-31T18:52:29.397+0000] {conn.py:1527} WARNING - DNS lookup failed for broker:29092, exception was [Errno -3] Temporary failure in name resolution. Is your advertised.listeners (called advertised.host.name before Kafka 9) correct and resolvable?
[2024-01-31T18:52:29.399+0000] {conn.py:315} ERROR - DNS lookup failed for broker:29092 (0)
[2024-01-31T18:52:29.401+0000] {conn.py:1205} INFO - Probing node bootstrap-0 broker version
[2024-01-31T18:52:37.407+0000] {conn.py:1527} WARNING - DNS lookup failed for broker:29092, exception was [Errno -3] Temporary failure in name resolution. Is your advertised.listeners (called advertised.host.name before Kafka 9) correct and resolvable?
[2024-01-31T18:52:37.409+0000] {conn.py:315} ERROR - DNS lookup failed for broker:29092 (0)
[2024-01-31T18:52:37.411+0000] {taskinstance.py:1943} ERROR - Task failed with exception
Traceback (most recent call last):
  File "/home/airflow/.local/lib/python3.9/site-packages/airflow/operators/python.py", line 192, in execute
    return_value = self.execute_callable()
  File "/home/airflow/.local/lib/python3.9/site-packages/airflow/operators/python.py", line 209, in execute_callable
    return self.python_callable(*self.op_args, **self.op_kwargs)
  File "/opt/airflow/dags/kafkastream.py", line 45, in stream_data
    producer = KafkaProducer(bootstrap_servers=['broker:29092'], max_block_ms=5000)
  File "/home/airflow/.local/lib/python3.9/site-packages/kafka/producer/kafka.py", line 381, in __init__
    client = KafkaClient(metrics=self._metrics, metric_group_prefix='producer',
  File "/home/airflow/.local/lib/python3.9/site-packages/kafka/client_async.py", line 244, in __init__
    self.config['api_version'] = self.check_version(timeout=check_timeout)
  File "/home/airflow/.local/lib/python3.9/site-packages/kafka/client_async.py", line 927, in check_version
    raise Errors.NoBrokersAvailable()
kafka.errors.NoBrokersAvailable: NoBrokersAvailable
[2024-01-31T18:52:37.446+0000] {taskinstance.py:1400} INFO - Marking task as FAILED. dag_id=user_automation, task_id=stream_data_from_api, execution_date=20240131T185217, start_date=20240131T185220, end_date=20240131T185237
[2024-01-31T18:52:37.470+0000] {standard_task_runner.py:104} ERROR - Failed to execute job 26 for task stream_data_from_api (NoBrokersAvailable; 51)
[2024-01-31T18:52:37.497+0000] {local_task_job_runner.py:228} INFO - Task exited with return code 1
[2024-01-31T18:52:37.522+0000] {taskinstance.py:2784} INFO - 0 downstream tasks scheduled from follow-on schedule check
